Traceback (most recent call last):
  File "E:\MainHomePage\.M_HomePage\Lib\site-packages\jupyter_cache\executors\utils.py", line 58, in single_nb_execution
    executenb(
  File "E:\MainHomePage\.M_HomePage\Lib\site-packages\nbclient\client.py", line 1314, in execute
    return NotebookClient(nb=nb, resources=resources, km=km, **kwargs).execute()
           ^^^^^^^^^^^^^^^^^^^^^^^^^^^^^^^^^^^^^^^^^^^^^^^^^^^^^^^^^^^^^^^^^^^^^
  File "E:\MainHomePage\.M_HomePage\Lib\site-packages\jupyter_core\utils\__init__.py", line 165, in wrapped
    return loop.run_until_complete(inner)
           ^^^^^^^^^^^^^^^^^^^^^^^^^^^^^^
  File "C:\Users\Dr\AppData\Local\Programs\Python\Python312\Lib\asyncio\base_events.py", line 687, in run_until_complete
    return future.result()
           ^^^^^^^^^^^^^^^
  File "E:\MainHomePage\.M_HomePage\Lib\site-packages\nbclient\client.py", line 709, in async_execute
    await self.async_execute_cell(
  File "E:\MainHomePage\.M_HomePage\Lib\site-packages\nbclient\client.py", line 1062, in async_execute_cell
    await self._check_raise_for_error(cell, cell_index, exec_reply)
  File "E:\MainHomePage\.M_HomePage\Lib\site-packages\nbclient\client.py", line 918, in _check_raise_for_error
    raise CellExecutionError.from_cell_and_msg(cell, exec_reply_content)
nbclient.exceptions.CellExecutionError: An error occurred while executing the following cell:
------------------
from PySpice.Spice.Netlist import Circuit
from PySpice.Unit import *
from PySpice.Logging.Logging import setup_logging

# Enable logging for PySpice
setup_logging()

# Create the Thevenin circuit
thevenin_circuit = Circuit('Thevenin Circuit')

# Define the components
thevenin_circuit.V(1, '1', thevenin_circuit.gnd, 10@u_V)  # 10V voltage source
thevenin_circuit.I(1, '2', '3', 100@u_mA)  # 0.1A current source
thevenin_circuit.R(1, '1', thevenin_circuit.gnd, 1@u_kÎ©)  # Resistors
thevenin_circuit.R(2, '1', '2', 1@u_kÎ©)
thevenin_circuit.R(3, '3', thevenin_circuit.gnd, 1@u_kÎ©)
thevenin_circuit.R(4, '2', thevenin_circuit.gnd, 1@u_kÎ©)
thevenin_circuit.R(5, '2', 'a', 1@u_kÎ©)  # Load resistor connection
thevenin_circuit.R(6, 'a', thevenin_circuit.gnd, 1@u_kÎ©)
------------------


[1;31m---------------------------------------------------------------------------[0m
[1;31mModuleNotFoundError[0m                       Traceback (most recent call last)
Cell [1;32mIn[1], line 1[0m
[1;32m----> 1[0m [38;5;28;01mfrom[39;00m [38;5;21;01mPySpice[39;00m[38;5;21;01m.[39;00m[38;5;21;01mSpice[39;00m[38;5;21;01m.[39;00m[38;5;21;01mNetlist[39;00m [38;5;28;01mimport[39;00m Circuit
[0;32m      2[0m [38;5;28;01mfrom[39;00m [38;5;21;01mPySpice[39;00m[38;5;21;01m.[39;00m[38;5;21;01mUnit[39;00m [38;5;28;01mimport[39;00m [38;5;241m*[39m
[0;32m      3[0m [38;5;28;01mfrom[39;00m [38;5;21;01mPySpice[39;00m[38;5;21;01m.[39;00m[38;5;21;01mLogging[39;00m[38;5;21;01m.[39;00m[38;5;21;01mLogging[39;00m [38;5;28;01mimport[39;00m setup_logging

[1;31mModuleNotFoundError[0m: No module named 'PySpice'

